Traceback (most recent call last):
  File "/home/sa7270/diffusion/run_experiment.py", line 44, in <module>
    diffusion.run()
  File "/home/sa7270/diffusion/diffusion.py", line 54, in run
    self.generate_data()
  File "/home/sa7270/diffusion/diffusion.py", line 41, in generate_data
    self.X_train.gen_x1_xt()
  File "/home/sa7270/diffusion/data.py", line 49, in gen_x1_xt
    self.X_t.to(self.device), self.X1.to(self.device)
AttributeError: 'Data' object has no attribute 'X1'. Did you mean: 'X_1'?
